<testsuite name="Django Project Tests" errors="2" failures="0" skips="0" tests="2" time="0.001"><testcase time="0.000000" classname="unittest.loader._FailedTest" name="test.venv.Lib.site-packages.setuptools"><error type="builtins.ImportError" message="Failed to import test module: test.venv.Lib.site-packages.setuptools&#10;Traceback (most recent call last):&#10;  File &quot;C:\Users\Ashraf\AppData\Local\Programs\Python\Python38-32\lib\unittest\loader.py&quot;, line 470, in _find_test_path&#10;    package = self._get_module_from_name(name)&#10;  File &quot;C:\Users\Ashraf\AppData\Local\Programs\Python\Python38-32\lib\unittest\loader.py&quot;, line 377, in _get_module_from_name&#10;    __import__(name)&#10;  File &quot;C:\Users\Ashraf\Desktop\BookWorm Project\test\venv\Lib\site-packages\setuptools\__init__.py&quot;, line 14, in &lt;module&gt;&#10;    from setuptools.dist import Distribution, Feature&#10;ImportError: cannot import name 'Feature' from 'setuptools.dist' (C:\Users\Ashraf\AppData\Local\Programs\Python\Python38-32\lib\site-packages\setuptools\dist.py)&#10;">ImportError: Failed to import test module: test.venv.Lib.site-packages.setuptools
Traceback (most recent call last):
  File "C:\Users\Ashraf\AppData\Local\Programs\Python\Python38-32\lib\unittest\loader.py", line 470, in _find_test_path
    package = self._get_module_from_name(name)
  File "C:\Users\Ashraf\AppData\Local\Programs\Python\Python38-32\lib\unittest\loader.py", line 377, in _get_module_from_name
    __import__(name)
  File "C:\Users\Ashraf\Desktop\BookWorm Project\test\venv\Lib\site-packages\setuptools\__init__.py", line 14, in &lt;module&gt;
    from setuptools.dist import Distribution, Feature
ImportError: cannot import name 'Feature' from 'setuptools.dist' (C:\Users\Ashraf\AppData\Local\Programs\Python\Python38-32\lib\site-packages\setuptools\dist.py)

</error></testcase><testcase time="0.000000" classname="unittest.loader._FailedTest" name="test.venv.Lib.site-packages.typed_ast.tests.test_basics"><error type="builtins.ImportError" message="Failed to import test module: test.venv.Lib.site-packages.typed_ast.tests.test_basics&#10;Traceback (most recent call last):&#10;  File &quot;C:\Users\Ashraf\AppData\Local\Programs\Python\Python38-32\lib\unittest\loader.py&quot;, line 436, in _find_test_path&#10;    module = self._get_module_from_name(name)&#10;  File &quot;C:\Users\Ashraf\AppData\Local\Programs\Python\Python38-32\lib\unittest\loader.py&quot;, line 377, in _get_module_from_name&#10;    __import__(name)&#10;  File &quot;C:\Users\Ashraf\Desktop\BookWorm Project\test\venv\Lib\site-packages\typed_ast\tests\test_basics.py&quot;, line 5, in &lt;module&gt;&#10;    from typed_ast import _ast3&#10;ModuleNotFoundError: No module named 'typed_ast'&#10;">ImportError: Failed to import test module: test.venv.Lib.site-packages.typed_ast.tests.test_basics
Traceback (most recent call last):
  File "C:\Users\Ashraf\AppData\Local\Programs\Python\Python38-32\lib\unittest\loader.py", line 436, in _find_test_path
    module = self._get_module_from_name(name)
  File "C:\Users\Ashraf\AppData\Local\Programs\Python\Python38-32\lib\unittest\loader.py", line 377, in _get_module_from_name
    __import__(name)
  File "C:\Users\Ashraf\Desktop\BookWorm Project\test\venv\Lib\site-packages\typed_ast\tests\test_basics.py", line 5, in &lt;module&gt;
    from typed_ast import _ast3
ModuleNotFoundError: No module named 'typed_ast'

</error></testcase></testsuite>